<?xml version="1.0" encoding="utf-8" ?>
<!-- This URDF was automatically created by SolidWorks to URDF Exporter! Originally created by Stephen Brawner (brawner@gmail.com) 
     Commit Version: 1.6.0-4-g7f85cfe  Build Version: 1.6.7995.38578
     For more information, please see http://wiki.ros.org/sw_urdf_exporter -->
<robot name="jibot3">
    <link name ="world"/>
    <joint name="world_joint" type="fixed">
        <origin xyz="0 0 0.01" rpy="0 0 0" />
        <parent link="world" />
        <child link="base_link" />
    </joint>
    <link name="base_link">
        <inertial>
            <origin xyz="0.0018187505335656 3.36120860971543E-05 0.0242076964406479" rpy="0 0 0" />
            <mass value="0.159097503800229" />
            <inertia ixx="0.000242702497862633" ixy="1.48409641546002E-10" ixz="6.59390553688888E-09" iyy="0.00024901097549793" iyz="3.27177094856132E-10" izz="0.00048225370265096" />
        </inertial>
        <visual>
            <origin xyz="0 0 0" rpy="0 0 0" />
            <geometry>
                <mesh filename="package://jibot3/meshes/base_link.STL" />
            </geometry>
            <material name="">
                <color rgba="0.792156862745098 0.819607843137255 0.933333333333333 1" />
            </material>
        </visual>
        <collision>
            <origin xyz="0 0 0" rpy="0 0 0" />
            <geometry>
                <mesh filename="package://jibot3/meshes/base_link.STL" />
            </geometry>
        </collision>
    </link>
    <link name="link1">
        <inertial>
            <origin xyz="4.2284E-06 -0.00067008 -0.0016359" rpy="0 0 0" />
            <mass value="0.027494" />
            <inertia ixx="1.2378E-05" ixy="-5.1601E-15" ixz="1.1927E-21" iyy="9.4098E-06" iyz="-6.6562E-21" izz="1.9507E-05" />
        </inertial>
        <visual>
            <origin xyz="0 0 0" rpy="0 0 0" />
            <geometry>
                <mesh filename="package://jibot3/meshes/link1.STL" />
            </geometry>
            <material name="">
                <color rgba="0.79216 0.81961 0.93333 1" />
            </material>
        </visual>
        <collision>
            <origin xyz="0 0 0" rpy="0 0 0" />
            <geometry>
                <mesh filename="package://jibot3/meshes/link1.STL" />
            </geometry>
        </collision>
    </link>
    <joint name="joint1" type="revolute">
        <origin xyz="6.7228E-05 0 0.064" rpy="0 0 0" />
        <parent link="base_link" />
        <child link="link1" />
        <axis xyz="-0.0010504 0 -1" />
        <limit lower="-3.14" upper="3.14" effort="100" velocity="1" />
    </joint>
    <link name="link2">
        <inertial>
            <origin xyz="-0.000973822925902236 0.000363676462313195 0.0446464826258339" rpy="0 0 0" />
            <mass value="0.0701809699122063" />
            <inertia ixx="2.07222626967255E-05" ixy="2.27619912113926E-12" ixz="5.16198262745135E-08" iyy="1.23651260156286E-05" iyz="4.49823552526448E-14" izz="1.30198440275529E-05" />
        </inertial>
        <visual>
            <origin xyz="0 0 0" rpy="0 0 0" />
            <geometry>
                <mesh filename="package://jibot3/meshes/link2.STL" />
            </geometry>
            <material name="">
                <color rgba="0.792156862745098 0.819607843137255 0.933333333333333 1" />
            </material>
        </visual>
        <collision>
            <origin xyz="0 0 0" rpy="0 0 0" />
            <geometry>
                <mesh filename="package://jibot3/meshes/link2.STL" />
            </geometry>
        </collision>
    </link>
    <joint name="joint2" type="revolute">
        <origin xyz="0.0001549 0 0.03211" rpy="0 0 0" />
        <parent link="link1" />
        <child link="link2" />
        <axis xyz="0.0029788 -0.99999 0.0019208" />
        <limit lower="-3.14" upper="3.14" effort="100" velocity="1" />
    </joint>
    <link name="link3">
        <inertial>
            <origin xyz="-0.00047222 0.00018988 0.055258" rpy="0 0 0" />
            <mass value="0.039324" />
            <inertia ixx="1.2773E-05" ixy="-1.2699E-08" ixz="2.3166E-07" iyy="7.2139E-06" iyz="4.3626E-08" izz="8.31E-06" />
        </inertial>
        <visual>
            <origin xyz="0 0 0" rpy="0 0 0" />
            <geometry>
                <mesh filename="package://jibot3/meshes/link3.STL" />
            </geometry>
            <material name="">
                <color rgba="0.79216 0.81961 0.93333 1" />
            </material>
        </visual>
        <collision>
            <origin xyz="0 0 0" rpy="0 0 0" />
            <geometry>
                <mesh filename="package://jibot3/meshes/link3.STL" />
            </geometry>
        </collision>
    </link>
    <joint name="joint3" type="revolute">
        <origin xyz="-0.000907427084811278 0 0.0892998909311206" rpy="0.0142798907320727 0.199900199023151 0.00283576473616103" />
        <parent link="link2" />
        <child link="link3" />
        <axis xyz="0.00531752735563392 0.999922661829751 -0.0112425202747712" />
        <limit lower="-3.14" upper="3.14" effort="100" velocity="1" />
    </joint>
    <link name="link4">
        <inertial>
            <origin xyz="-0.0088076 -1.979E-05 0.036104" rpy="0 0 0" />
            <mass value="0.038508" />
            <inertia ixx="9.0681E-06" ixy="1.1515E-09" ixz="2.922E-08" iyy="1.0847E-05" iyz="3.5793E-10" izz="7.1178E-06" />
        </inertial>
        <visual>
            <origin xyz="0 0 0" rpy="0 0 0" />
            <geometry>
                <mesh filename="package://jibot3/meshes/link4.STL" />
            </geometry>
            <material name="">
                <color rgba="0.79216 0.81961 0.93333 1" />
            </material>
        </visual>
        <collision>
            <origin xyz="0 0 0" rpy="0 0 0" />
            <geometry>
                <mesh filename="package://jibot3/meshes/link4.STL" />
            </geometry>
        </collision>
    </link>
    <joint name="joint4" type="revolute">
        <origin xyz="0 0 0.072906" rpy="-0.041043 1.2512 -0.041474" />
        <parent link="link3" />
        <child link="link4" />
        <axis xyz="0 -0.99999 -0.0034358" />
        <limit lower="-3.14" upper="3.14" effort="100" velocity="1" />
    </joint>
    <link name="link5">
        <inertial>
            <origin xyz="-0.000639896336568108 0.00121194848910335 0.0245764265664954" rpy="0 0 0" />
            <mass value="0.00735665479445383" />
            <inertia ixx="1.26759073778027E-06" ixy="-7.45749771716672E-16" ixz="3.40409485282715E-16" iyy="5.5165210855188E-07" iyz="-7.22885266722634E-14" izz="8.1467569020728E-07" />
        </inertial>
        <visual>
            <origin xyz="0 0 0" rpy="0 0 0" />
            <geometry>
                <mesh filename="package://jibot3/meshes/link5.STL" />
            </geometry>
            <material name="">
                <color rgba="0.792156862745098 0.819607843137255 0.933333333333333 1" />
            </material>
        </visual>
        <collision>
            <origin xyz="0 0 0" rpy="0 0 0" />
            <geometry>
                <mesh filename="package://jibot3/meshes/link5.STL" />
            </geometry>
        </collision>
    </link>
    <joint name="joint5" type="revolute">
        <origin xyz="-0.020947 -0.00013895 0.061179" rpy="0 0 -0.01996" />
        <parent link="link4" />
        <child link="link5" />
        <axis xyz="0 0 -1" />
        <limit lower="-3.14" upper="3.14" effort="100" velocity="1" />
    </joint>
    <link name="link6_1">
        <inertial>
            <origin xyz="0.0068461 -0.0060882 0.00037705" rpy="0 0 0" />
            <mass value="0.00218" />
            <inertia ixx="2.0757E-07" ixy="1.221E-07" ixz="1.8435E-08" iyy="1.8558E-07" iyz="-1.0888E-08" izz="3.7886E-07" />
        </inertial>
        <visual>
            <origin xyz="0 0 0" rpy="0 0 0" />
            <geometry>
                <mesh filename="package://jibot3/meshes/link6_1.STL" />
            </geometry>
            <material name="">
                <color rgba="0.79216 0.81961 0.93333 1" />
            </material>
        </visual>
        <collision>
            <origin xyz="0 0 0" rpy="0 0 0" />
            <geometry>
                <mesh filename="package://jibot3/meshes/link6_1.STL" />
            </geometry>
        </collision>
    </link>
    <joint name="joint6_1" type="revolute">
        <origin xyz="0.004 0.013725 0.029515" rpy="-3.1416 -1.4514 0.019089" />
        <parent link="link5" />
        <child link="link6_1" />
        <axis xyz="-0.11906 -0.019088 -0.9927" />
        <limit lower="-3.14" upper="3.14" effort="100" velocity="1" />
    </joint>
    <link name="link7_1">
        <inertial>
            <origin xyz="0.0230770307506878 0.0035591840287565 0.00315287503519782" rpy="0 0 0" />
            <mass value="0.0029527905178879" />
            <inertia ixx="7.82407226199894E-08" ixy="-1.67583252334009E-07" ixz="4.01728848553185E-17" iyy="7.05476569519731E-07" iyz="2.1346757122142E-16" izz="7.6403656595074E-07" />
        </inertial>
        <visual>
            <origin xyz="0 0 0" rpy="0 0 0" />
            <geometry>
                <mesh filename="package://jibot3/meshes/link7_1.STL" />
            </geometry>
            <material name="">
                <color rgba="0.792156862745098 0.819607843137255 0.933333333333333 1" />
            </material>
        </visual>
        <collision>
            <origin xyz="0 0 0" rpy="0 0 0" />
            <geometry>
                <mesh filename="package://jibot3/meshes/link7_1.STL" />
            </geometry>
        </collision>
    </link>
    <joint name="joint7_1" type="revolute">
        <origin xyz="0.021184 -0.021187 -0.0021332" rpy="-3.1067 0.11574 0.45284" />
        <parent link="link6_1" />
        <child link="link7_1" />
        <axis xyz="0 0 -1" />
        <limit lower="-3.14" upper="3.14" effort="100" velocity="1" />
    </joint>
    <link name="link6_2">
        <inertial>
            <origin xyz="0.00647030714889267 0.00581952170150188 0.000217281850265649" rpy="0 0 0" />
            <mass value="0.00230959501633935" />
            <inertia ixx="2.11956696320674E-07" ixy="-1.24112138593459E-07" ixz="2.34958449174616E-08" iyy="1.89668888200061E-07" iyz="1.8697936550651E-08" izz="3.84790568959189E-07" />
        </inertial>
        <visual>
            <origin xyz="0 0 0" rpy="0 0 0" />
            <geometry>
                <mesh filename="package://jibot3/meshes/link6_2.STL" />
            </geometry>
            <material name="">
                <color rgba="0.792156862745098 0.819607843137255 0.933333333333333 1" />
            </material>
        </visual>
        <collision>
            <origin xyz="0 0 0" rpy="0 0 0" />
            <geometry>
                <mesh filename="package://jibot3/meshes/link6_2.STL" />
            </geometry>
        </collision>
    </link>
    <joint name="joint6_2" type="revolute">
        <origin xyz="0.004 -0.013694 0.029489" rpy="-3.1416 -1.4514 0.019089" />
        <parent link="link5" />
        <child link="link6_2" />
        <axis xyz="0.11906 0.019088 0.9927" />
        <limit lower="-3.14" upper="3.14" effort="100" velocity="1" />
    </joint>
    <link name="link7_2">
        <inertial>
            <origin xyz="0.023072 -0.0036182 0.0031529" rpy="0 0 0" />
            <mass value="0.0029528" />
            <inertia ixx="7.8241E-08" ixy="1.6758E-07" ixz="1.9212E-16" iyy="7.0548E-07" iyz="1.0135E-16" izz="7.6404E-07" />
        </inertial>
        <visual>
            <origin xyz="0 0 0" rpy="0 0 0" />
            <geometry>
                <mesh filename="package://jibot3/meshes/link7_2.STL" />
            </geometry>
            <material name="">
                <color rgba="0.79216 0.81961 0.93333 1" />
            </material>
        </visual>
        <collision>
            <origin xyz="0 0 0" rpy="0 0 0" />
            <geometry>
                <mesh filename="package://jibot3/meshes/link7_2.STL" />
            </geometry>
        </collision>
    </link>
    <joint name="joint7_2" type="revolute">
        <origin xyz="0.021092 0.021163 -0.0029365" rpy="3.0724 0.099166 -0.45197" />
        <parent link="link6_2" />
        <child link="link7_2" />
        <axis xyz="0 0 -1" />
        <limit lower="-3.14" upper="3.14" effort="100" velocity="1" />
    </joint>
    <transmission name="trans_joint1">
        <type>transmission_interface/SimpleTransmission</type>
        <joint name="joint1">
            <hardwareInterface>hardware_interface/PositionJointInterface</hardwareInterface>
        </joint>
        <actuator name="joint1_motor">
            <hardwareInterface>hardware_interface/PositionJointInterface</hardwareInterface>
            <mechanicalReduction>1</mechanicalReduction>
        </actuator>
    </transmission>
    <transmission name="trans_joint2">
        <type>transmission_interface/SimpleTransmission</type>
        <joint name="joint2">
            <hardwareInterface>hardware_interface/PositionJointInterface</hardwareInterface>
        </joint>
        <actuator name="joint2_motor">
            <hardwareInterface>hardware_interface/PositionJointInterface</hardwareInterface>
            <mechanicalReduction>1</mechanicalReduction>
        </actuator>
    </transmission>
    <transmission name="trans_joint3">
        <type>transmission_interface/SimpleTransmission</type>
        <joint name="joint3">
            <hardwareInterface>hardware_interface/PositionJointInterface</hardwareInterface>
        </joint>
        <actuator name="joint3_motor">
            <hardwareInterface>hardware_interface/PositionJointInterface</hardwareInterface>
            <mechanicalReduction>1</mechanicalReduction>
        </actuator>
    </transmission>
    <transmission name="trans_joint4">
        <type>transmission_interface/SimpleTransmission</type>
        <joint name="joint4">
            <hardwareInterface>hardware_interface/PositionJointInterface</hardwareInterface>
        </joint>
        <actuator name="joint4_motor">
            <hardwareInterface>hardware_interface/PositionJointInterface</hardwareInterface>
            <mechanicalReduction>1</mechanicalReduction>
        </actuator>
    </transmission>
    <transmission name="trans_joint5">
        <type>transmission_interface/SimpleTransmission</type>
        <joint name="joint5">
            <hardwareInterface>hardware_interface/PositionJointInterface</hardwareInterface>
        </joint>
        <actuator name="joint5_motor">
            <hardwareInterface>hardware_interface/PositionJointInterface</hardwareInterface>
            <mechanicalReduction>1</mechanicalReduction>
        </actuator>
    </transmission>
    <transmission name="trans_joint6_1">
        <type>transmission_interface/SimpleTransmission</type>
        <joint name="joint6_1">
            <hardwareInterface>hardware_interface/PositionJointInterface</hardwareInterface>
        </joint>
        <actuator name="joint6_1_motor">
            <hardwareInterface>hardware_interface/PositionJointInterface</hardwareInterface>
            <mechanicalReduction>1</mechanicalReduction>
        </actuator>
    </transmission>
    <transmission name="trans_joint7_1">
        <type>transmission_interface/SimpleTransmission</type>
        <joint name="joint7_1">
            <hardwareInterface>hardware_interface/PositionJointInterface</hardwareInterface>
        </joint>
        <actuator name="joint7_1_motor">
            <hardwareInterface>hardware_interface/PositionJointInterface</hardwareInterface>
            <mechanicalReduction>1</mechanicalReduction>
        </actuator>
    </transmission>
    <transmission name="trans_joint6_2">
        <type>transmission_interface/SimpleTransmission</type>
        <joint name="joint6_2">
            <hardwareInterface>hardware_interface/PositionJointInterface</hardwareInterface>
        </joint>
        <actuator name="joint6_2_motor">
            <hardwareInterface>hardware_interface/PositionJointInterface</hardwareInterface>
            <mechanicalReduction>1</mechanicalReduction>
        </actuator>
    </transmission>
    <transmission name="trans_joint7_2">
        <type>transmission_interface/SimpleTransmission</type>
        <joint name="joint7_2">
            <hardwareInterface>hardware_interface/PositionJointInterface</hardwareInterface>
        </joint>
        <actuator name="joint7_2_motor">
            <hardwareInterface>hardware_interface/PositionJointInterface</hardwareInterface>
            <mechanicalReduction>1</mechanicalReduction>
        </actuator>
    </transmission>
    <gazebo>
        <plugin name="gazebo_ros_control" filename="libgazebo_ros_control.so">
            <robotNamespace>/</robotNamespace>
        </plugin>
    </gazebo>
    <gazebo reference="base_link">
        <material>Gazebo/Orange</material>
    </gazebo>
    <gazebo reference="link1">
        <material>Gazebo/Orange</material>
    </gazebo>
    <gazebo reference="link2">
        <material>Gazebo/Orange</material>
    </gazebo>
    <gazebo reference="link3">
        <material>Gazebo/Orange</material>
    </gazebo>
    <gazebo reference="link4">
        <material>Gazebo/Orange</material>
    </gazebo>
    <gazebo reference="link5">
        <material>Gazebo/Orange</material>
    </gazebo>
    <gazebo reference="link6_1">
        <material>Gazebo/Orange</material>
    </gazebo>
    <gazebo reference="link7_1">
        <material>Gazebo/Orange</material>
    </gazebo>
    <gazebo reference="link6_2">
        <material>Gazebo/Orange</material>
    </gazebo>
    <gazebo reference="link7_2">
        <material>Gazebo/Orange</material>
    </gazebo>
</robot>

